Traceback (most recent call last):
  File "/opt/conda/lib/python3.11/site-packages/transformers/utils/hub.py", line 403, in cached_file
    resolved_file = hf_hub_download(
                    ^^^^^^^^^^^^^^^^
  File "/opt/conda/lib/python3.11/site-packages/huggingface_hub/utils/_deprecation.py", line 101, in inner_f
    return f(*args, **kwargs)
           ^^^^^^^^^^^^^^^^^^
  File "/opt/conda/lib/python3.11/site-packages/huggingface_hub/utils/_validators.py", line 106, in _inner_fn
    validate_repo_id(arg_value)
  File "/opt/conda/lib/python3.11/site-packages/huggingface_hub/utils/_validators.py", line 154, in validate_repo_id
    raise HFValidationError(
huggingface_hub.errors.HFValidationError: Repo id must be in the form 'repo_name' or 'namespace/repo_name': '../hf_model_comp/qtip/hf/vicuna_7b_v1.5/2bit_e2e_ft'. Use `repo_type` argument if needed.

The above exception was the direct cause of the following exception:

Traceback (most recent call last):
  File "<frozen runpy>", line 198, in _run_module_as_main
  File "<frozen runpy>", line 88, in _run_code
  File "/workspace/Weight_compression/qtip/eval/eval_zeroshot.py", line 92, in <module>
    main(args)
  File "/workspace/Weight_compression/qtip/eval/eval_zeroshot.py", line 33, in main
    model, model_str = model_from_hf_path(args.hf_path, max_mem_ratio=args.max_mem_ratio, device_map='balanced')
                       ^^^^^^^^^^^^^^^^^^^^^^^^^^^^^^^^^^^^^^^^^^^^^^^^^^^^^^^^^^^^^^^^^^^^^^^^^^^^^^^^^^^^^^^^^
  File "/workspace/Weight_compression/qtip/lib/utils/unsafe_import.py", line 18, in model_from_hf_path
    bad_config = transformers.AutoConfig.from_pretrained(path)
                 ^^^^^^^^^^^^^^^^^^^^^^^^^^^^^^^^^^^^^^^^^^^^^
  File "/opt/conda/lib/python3.11/site-packages/transformers/models/auto/configuration_auto.py", line 1006, in from_pretrained
    config_dict, unused_kwargs = PretrainedConfig.get_config_dict(pretrained_model_name_or_path, **kwargs)
                                 ^^^^^^^^^^^^^^^^^^^^^^^^^^^^^^^^^^^^^^^^^^^^^^^^^^^^^^^^^^^^^^^^^^^^^^^^^
  File "/opt/conda/lib/python3.11/site-packages/transformers/configuration_utils.py", line 570, in get_config_dict
    config_dict, kwargs = cls._get_config_dict(pretrained_model_name_or_path, **kwargs)
                          ^^^^^^^^^^^^^^^^^^^^^^^^^^^^^^^^^^^^^^^^^^^^^^^^^^^^^^^^^^^^^
  File "/opt/conda/lib/python3.11/site-packages/transformers/configuration_utils.py", line 629, in _get_config_dict
    resolved_config_file = cached_file(
                           ^^^^^^^^^^^^
  File "/opt/conda/lib/python3.11/site-packages/transformers/utils/hub.py", line 469, in cached_file
    raise EnvironmentError(
OSError: Incorrect path_or_model_id: '../hf_model_comp/qtip/hf/vicuna_7b_v1.5/2bit_e2e_ft'. Please provide either the path to a local folder or the repo_id of a model on the Hub.
