Traceback (most recent call last):
  File "/opt/conda/lib/python3.10/site-packages/transformers/utils/hub.py", line 403, in cached_file
    resolved_file = hf_hub_download(
  File "/opt/conda/lib/python3.10/site-packages/huggingface_hub/utils/_validators.py", line 106, in _inner_fn
    validate_repo_id(arg_value)
  File "/opt/conda/lib/python3.10/site-packages/huggingface_hub/utils/_validators.py", line 154, in validate_repo_id
    raise HFValidationError(
huggingface_hub.errors.HFValidationError: Repo id must be in the form 'repo_name' or 'namespace/repo_name': './hf/noft_had_rescale//meta-llama--Llama-2-7b-hf/lmbda1000'. Use `repo_type` argument if needed.

The above exception was the direct cause of the following exception:

Traceback (most recent call last):
  File "/workspace/Weight_compression/comp_lm_qtip/eval_ppl.py", line 124, in <module>
    main(args)
  File "/workspace/Weight_compression/comp_lm_qtip/eval_ppl.py", line 71, in main
    model, model_str = model_from_hf_path(
  File "/workspace/Weight_compression/comp_lm_qtip/eval_ppl.py", line 49, in model_from_hf_path
    model = maybe_wrap(use_cuda_graph)(model_cls).from_pretrained(
  File "/opt/conda/lib/python3.10/site-packages/transformers/models/auto/auto_factory.py", line 487, in from_pretrained
    resolved_config_file = cached_file(
  File "/opt/conda/lib/python3.10/site-packages/transformers/utils/hub.py", line 469, in cached_file
    raise EnvironmentError(
OSError: Incorrect path_or_model_id: './hf/noft_had_rescale//meta-llama--Llama-2-7b-hf/lmbda1000'. Please provide either the path to a local folder or the repo_id of a model on the Hub.
